Workbook

Sheet Sheet1
A1: Level | B1: XP to next Lvl. | C1: Total XP
A2: 1 | B2: 2500 | C2: 0
A3: 2 | B3: =C4-C3 -> 3000 | C3: 2500
A4: 3 | B4: =C5-C4 -> 3500 | C4: 5500
A5: 4 | B5: =C6-C5 -> 4000 | C5: 9000
A6: 5 | B6: =C7-C6 -> 5000 | C6: 13000
A7: 6 | B7: =C8-C7 -> 6000 | C7: 18000
A8: 7 | B8: =C9-C8 -> 7000 | C8: 24000
A9: 8 | B9: =C10-C9 -> 8000 | C9: 31000
A10: 9 | B10: =C11-C10 -> 9000 | C10: 39000
A11: 10 | B11: =C12-C11 -> 10000 | C11: 48000
A12: 11 | B12: =C13-C12 -> 12000 | C12: 58000
A13: 12 | B13: =C14-C13 -> 14000 | C13: 70000
A14: 13 | B14: =C15-C14 -> 16000 | C14: 84000
... A18: 17 | B18: =C19-C18 -> 28500 | C18: 163000
A19: 18 | B19: =IF(C20-C19<0,0,C20-C19) -> 31500 | C19: 191500
A20: 19 | B20: =IF(C21-C20<0,0,C21-C20) -> 35000 | C20: 223000
A21: 20 | B21: =IF(C22-C21<0,0,C22-C21) -> 42000 | C21: 258000
A22: 21 | B22: =IF(C23-C22<0,0,C23-C22) -> 49000 | C22: 300000
A23: 22 | B23: =IF(C24-C23<0,0,C24-C23) -> 56000 | C23: 349000
A24: 23 | B24: =IF(C25-C24<0,0,C25-C24) -> 63000 | C24: 405000
A25: 24 | B25: =IF(C26-C25<0,0,C26-C25) -> 70000 | C25: 468000
A26: 25 | B26: =IF(C27-C26<0,0,C27-C26) -> 83000 | C26: 538000
A27: 26 | B27: =IF(C28-C27<0,0,C28-C27) -> 96000 | C27: 621000
A28: 27 | B28: =IF(C29-C28<0,0,C29-C28) -> 109000 | C28: 717000
A29: 28 | B29: =IF(C30-C29<0,0,C30-C29) -> 122000 | C29: 826000
A30: 29 | B30: =IF(C31-C30<0,0,C31-C30) -> 135000 | C30: 948000
... A32: 31 | B32: =IF(C33-C32<0,0,C33-C32) -> 181000 | C32: 1241000
A33: 32 | B33: =IF(C34-C33<0,0,C34-C33) -> 204000 | C33: =D33*1000 -> 1422000 | D33: 1422
A34: 33 | B34: =IF(C35-C34<0,0,C35-C34) -> 227000 | C34: =D34*1000 -> 1626000 | D34: 1626
A35: 34 | B35: =IF(C36-C35<0,0,C36-C35) -> 250000 | C35: =D35*1000 -> 1853000 | D35: 1853
A36: 35 | B36: =IF(C37-C36<0,0,C37-C36) -> 290000 | C36: =D36*1000 -> 2103000 | D36: 2103
A37: 36 | B37: =IF(C38-C37<0,0,C38-C37) -> 330000 | C37: =D37*1000 -> 2393000 | D37: 2393
A38: 37 | B38: =IF(C39-C38<0,0,C39-C38) -> 370000 | C38: =D38*1000 -> 2723000 | D38: 2723
A39: 38 | B39: =IF(C40-C39<0,0,C40-C39) -> 410000 | C39: =D39*1000 -> 3093000 | D39: 3093
A40: 39 | B40: =IF(C41-C40<0,0,C41-C40) -> 450000 | C40: =D40*1000 -> 3503000 | D40: 3503
A41: 40 | B41: =IF(C42-C41<0,0,C42-C41) -> 520000 | C41: =D41*1000 -> 3953000 | D41: 3953
A42: 41 | B42: =IF(C43-C42<0,0,C43-C42) -> 590000 | C42: =D42*1000 -> 4473000 | D42: 4473
A43: 42 | B43: =IF(C44-C43<0,0,C44-C43) -> 660000 | C43: =D43*1000 -> 5063000 | D43: 5063
A44: 43 | B44: =IF(C45-C44<0,0,C45-C44) -> 730000 | C44: =D44*1000 -> 5723000 | D44: 5723
...

Sheet Sheet2
A1: Spieler | B1: Total XP | C1: Lvl | D1: Lvl XP | E1: XP Bar
A2: Thombay | B2: =D2+E2 -> 92387860 | C2: 70 | D2: {=INDEX(Sheet1!$C:$C, Sheet2!C2+1)} -> 85853000 | E2: 6534860 | G2: 70 | H2: 6821968
A3: Cerius | B3: =D3+E3 -> 31110883 | C3: 58 | D3: {=INDEX(Sheet1!$C:$C, Sheet2!C3+1)} -> 28553000 | E3: 2557883 | F3: {=INDEX(Sheet1!$C:$C, Sheet2!G3+1)+H3} -> 31292886 | G3: 58 | H3: 2739886
A4: Thomzay | B4: =D4+E4 -> 11383685 | C4: 48 | D4: {=INDEX(Sheet1!$C:$C, Sheet2!C4+1)} -> 10253000 | E4: 1130685 | G4: 49 | H4: 3102
A5: Babsi | B5: =D5+E5 -> 60369937 | C5: 66 | D5: {=INDEX(Sheet1!$C:$C, Sheet2!C5+1)} -> 59853000 | E5: 516937 | G5: 66 | H5: 556837
A6: Martin | B6: =D6+E6 -> 24481080 | C6: 56 | D6: {=INDEX(Sheet1!$C:$C, Sheet2!C6+1)} -> 23553000 | E6: 928080 | G6: 56 | H6: 1240955
A7: Paul | B7: =D7+E7 -> 15152583 | C7: 51 | D7: {=INDEX(Sheet1!$C:$C, Sheet2!C7+1)} -> 14193000 | E7: 959583 | G7: 51 | H7: 1001493
A8: Azog | B8: =D8+E8 -> 204426736 | C8: 70 | D8: {=INDEX(Sheet1!$C:$C, Sheet2!C8+1)} -> 85853000 | E8: 118573736 | G8: 71 | H8: 110784011
A9: Tastef | B9: =D9+E9 -> 349601345 | C9: 75 | D9: {=INDEX(Sheet1!$C:$C, Sheet2!C9+1)} -> 133353000 | E9: 216248345 | G9: 75 | H9: 217967141
